ERROR [2020-11-28 20:47:13] [petrivanov5493]  Message: 'chromedriver' executable needs to be in PATH. Please see https://sites.google.com/a/chromium.org/chromedriver/home
Traceback (most recent call last):
  File "/Users/vladimir/Desktop/PROJECT_INSTA_PARSER/env/lib/python3.7/site-packages/selenium/webdriver/common/service.py", line 76, in start
    stdin=PIPE)
  File "/Library/Frameworks/Python.framework/Versions/3.7/lib/python3.7/subprocess.py", line 775, in __init__
    restore_signals, start_new_session)
  File "/Library/Frameworks/Python.framework/Versions/3.7/lib/python3.7/subprocess.py", line 1522, in _execute_child
    raise child_exception_type(errno_num, err_msg, err_filename)
FileNotFoundError: [Errno 2] No such file or directory: '/Users/vladimir/Desktop/PROJECT_INSTA_PARSER/env/lib/python3.7/site-packages/assets/chromedriver': '/Users/vladimir/Desktop/PROJECT_INSTA_PARSER/env/lib/python3.7/site-packages/assets/chromedriver'

During handling of the above exception, another exception occurred:

Traceback (most recent call last):
  File "/Users/vladimir/Desktop/PROJECT_INSTA_PARSER/env/lib/python3.7/site-packages/instapy/browser.py", line 117, in set_selenium_local_session
    chrome_options=chrome_options)
  File "/Users/vladimir/Desktop/PROJECT_INSTA_PARSER/env/lib/python3.7/site-packages/selenium/webdriver/chrome/webdriver.py", line 73, in __init__
    self.service.start()
  File "/Users/vladimir/Desktop/PROJECT_INSTA_PARSER/env/lib/python3.7/site-packages/selenium/webdriver/common/service.py", line 83, in start
    os.path.basename(self.path), self.start_error_message)
selenium.common.exceptions.WebDriverException: Message: 'chromedriver' executable needs to be in PATH. Please see https://sites.google.com/a/chromium.org/chromedriver/home

ERROR [2020-11-28 20:52:54] [petrivanov5493]  Message: 'chromedriver' executable needs to be in PATH. Please see https://sites.google.com/a/chromium.org/chromedriver/home
Traceback (most recent call last):
  File "/Users/vladimir/Desktop/PROJECT_INSTA_PARSER/env/lib/python3.7/site-packages/selenium/webdriver/common/service.py", line 76, in start
    stdin=PIPE)
  File "/Library/Frameworks/Python.framework/Versions/3.7/lib/python3.7/subprocess.py", line 775, in __init__
    restore_signals, start_new_session)
  File "/Library/Frameworks/Python.framework/Versions/3.7/lib/python3.7/subprocess.py", line 1522, in _execute_child
    raise child_exception_type(errno_num, err_msg, err_filename)
FileNotFoundError: [Errno 2] No such file or directory: '/Users/vladimir/Desktop/PROJECT_INSTA_PARSER/env/lib/python3.7/site-packages/assets/chromedriver': '/Users/vladimir/Desktop/PROJECT_INSTA_PARSER/env/lib/python3.7/site-packages/assets/chromedriver'

During handling of the above exception, another exception occurred:

Traceback (most recent call last):
  File "/Users/vladimir/Desktop/PROJECT_INSTA_PARSER/env/lib/python3.7/site-packages/instapy/browser.py", line 117, in set_selenium_local_session
    chrome_options=chrome_options)
  File "/Users/vladimir/Desktop/PROJECT_INSTA_PARSER/env/lib/python3.7/site-packages/selenium/webdriver/chrome/webdriver.py", line 73, in __init__
    self.service.start()
  File "/Users/vladimir/Desktop/PROJECT_INSTA_PARSER/env/lib/python3.7/site-packages/selenium/webdriver/common/service.py", line 83, in start
    os.path.basename(self.path), self.start_error_message)
selenium.common.exceptions.WebDriverException: Message: 'chromedriver' executable needs to be in PATH. Please see https://sites.google.com/a/chromium.org/chromedriver/home

